Workbook

Sheet Pivot Tables
E3: Location/Cluster | F3: Count of Location/Cluster | H3: Question Type | I3: Count of Question Type | K3: Repeat Question (Yes/No) | L3: Count of Repeat Question (Yes/No)
E4: MIDC | F4: 52 | H4: Documents | I4: 39 | K4: No | L4: 37
E5: Mumbai Central | F5: 47 | H5: Holiday | I5: 1 | K5: (blank)
E6: (blank) | H6: Information | I6: 33 | K6: Yes | L6: 59
E7: Grand Total | F7: 99 | H7: (blank) | K7: Grand Total | L7: 96
H8: Grievance | I8: 26
H9: Grand Total | I9: 99 | K9: Notes Language | L9: Count of Notes Language
E10: Department (HR/Admin or Helpdesk) | F10: Count of Department (HR/Admin or Helpdesk) | K10: Hindi | L10: 64
E11: Helpdesk | F11: 57 | H11: Status | I11: Count of Status | K11: Marathi | L11: 35
E12: HR/Admin | F12: 18 | H12: Solved | I12: 78 | K12: (blank)
E13: (blank) | H13: (blank) | K13: Grand Total | L13: 99
E14: Production | F14: 23 | H14: Pending | I14: 21
E15: Others | F15: 1 | H15: Grand Total | I15: 99
E16: Grand Total | F16: 99

Sheet Dashboard

Sheet V2V
A1: Sr. No. | B1: Code | C1: Worker Name | D1: Employee Code | E1: Voice Note Received- date | F1: Location/Cluster | G1: Department (HR/Admin or Helpdesk) | H1: Question Type | I1: Department Spoc | J1: Date Sent to Department | K1: Notes Language | L1: Response Received Date | M1: Sent Back to Worker (Yes/No) | N1: Status | O1: Repeat Question (Yes/No) | P1: Remarks
A2: 1 | B2: HR_Ad_Q_1 | C2: Anjumbanu Salman Khan | D2: =VLOOKUP(C2,Workers!B:C,2) -> 508 | E2: 46041 | F2: Mumbai Central | G2: HR/Admin | H2: Holiday | I2: Grishma | J2: 46041 | K2: Hindi | L2: 46041 | M2: Yes | N2: Solved | O2: No
A3: 2 | B3: Hd_Q_1 | C3: Divya Sagar Pali | D3: =VLOOKUP(C3,Workers!B:C,2) -> 575 | E3: 46041 | F3: Mumbai Central | G3: Helpdesk | H3: Documents | I3: Dinesh | J3: 46042 | K3: Hindi | L3: 46042 | M3: Yes | N3: Solved | O3: No
A4: 3 | B4: Hd_Q_3 | C4: Hema Laxman Tele | D4: =VLOOKUP(C4,Workers!B:C,2) -> 23 | E4: 46042 | F4: MIDC | G4: Helpdesk | H4: Documents | I4: Priti | J4: 46042 | K4: Marathi | L4: 46042 | M4: Yes | N4: Solved | O4: No
A5: 4 | B5: Hd_Q_2 | C5: Karuna Krishna Gawade | D5: =VLOOKUP(C5,Workers!B:C,2) -> 32 | E5: 46042 | F5: MIDC | G5: Helpdesk | H5: Documents | I5: Priti | J5: 46042 | K5: Marathi | L5: 46042 | M5: Yes | N5: Solved | O5: No
A6: 5 | B6: Hd_Q_4 | C6: Seema Shambhu Bidlan | D6: =VLOOKUP(C6,Workers!B:C,2) -> 92 | E6: 46042 | F6: MIDC | G6: Helpdesk | H6: Documents | I6: Priti | J6: 46042 | K6: Hindi | L6: 46042 | M6: Yes | N6: Solved | O6: No
A7: 6 | B7: Hd_Q_5 | C7: Chanda Devi | D7: =VLOOKUP(C7,Workers!B:C,2) -> 12 | E7: 46042 | F7: MIDC | G7: Helpdesk | H7: Documents | I7: Priti | J7: 46042 | K7: Hindi | L7: 46042 | M7: Yes | N7: Solved | O7: No
A8: 7 | B8: Hd_Q_6 | C8: Sarika Anil Kamble | D8: =VLOOKUP(C8,Workers!B:C,2) -> 89 | E8: 46042 | F8: MIDC | G8: Helpdesk | H8: Information | I8: Priti | J8: 46042 | K8: Marathi | L8: 46042 | M8: Yes | N8: Solved | O8: No
A9: 8 | B9: Hd_Q_8 | C9: Seema Shambhu Bidlan | D9: =VLOOKUP(C9,Workers!B:C,2) -> 92 | E9: 46042 | F9: MIDC | G9: Helpdesk | H9: Information | I9: Priti | J9: 46042 | K9: Hindi | L9: 46043 | M9: Yes | N9: Solved | O9: No | P9: Follow up
A10: 9 | B10: Hd_Q_7 | C10: Sanchita Sujindra Ayake | D10: =VLOOKUP(C10,Workers!B:C,2) -> 85 | E10: 46043 | F10: MIDC | G10: Helpdesk | H10: Documents | I10: Priti | J10: 46043 | K10: Marathi | L10: 46043 | M10: Yes | N10: Solved | O10: No
A11: 10 | B11: Hd_Q_9 | C11: Leena Khandu Garud | D11: =VLOOKUP(C11,Workers!B:C,2) -> 39 | E11: 46043 | F11: MIDC | G11: Helpdesk | H11: Documents | I11: Priti | J11: 46043 | K11: Marathi | L11: 46043 | M11: Yes | N11: Solved | O11: No
A12: 11 | B12: Hd_Q_10 | C12: Nirmala Rammilan Prajapati | D12: =VLOOKUP(C12,Workers!B:C,2) -> 238 | E12: 46043 | F12: MIDC | G12: Helpdesk | H12: Information | I12: Priti | J12: 46043 | K12: Hindi | L12: 46043 | M12: Yes | N12: Solved | O12: No
A13: 12 | B13: Hd_Q_11 | C13: Sandhya Sanjay Pawar | D13: =VLOOKUP(C13,Workers!B:C,2) -> 214 | E13: 46043 | F13: MIDC | G13: Helpdesk | H13: Documents | I13: Priti | J13: 46043 | K13: Marathi | L13: 46043 | M13: Yes | N13: Solved | O13: No
A14: 13 | B14: Hd_Q_12 | C14: Pramila Bhagwan Jadhav | D14: =VLOOKUP(C14,Workers!B:C,2) -> 61 | E14: 46043 | F14: MIDC | G14: Helpdesk | H14: Documents | I14: Priti | J14: 46043 | K14: Marathi | L14: 46043 | M14: Yes | N14: Solved | O14: No
A15: 14 | B15: Hd_Q_13 | C15: Beby Navsha Baraf | D15: =VLOOKUP(C15,Workers!B:C,2) -> 10 | E15: 46043 | F15: MIDC | G15: Helpdesk | H15: Information | I15: Priti | J15: 46043 | K15: Marathi | L15: 46043 | M15: Yes | N15: Solved | O15: No
A16: 15 | B16: Hd_Q_14 | C16: Varsha Pappu Kirkire | D16: =VLOOKUP(C16,Workers!B:C,2) -> 116 | E16: 46043 | F16: MIDC | G16: Helpdesk | H16: Information | I16: Priti | J16: 46043 | K16: Marathi | L16: 46043 | M16: Yes | N16: Solved | O16: Yes | P16: Aadhar delivery
A17: 16 | B17: Hd_Q_16 | C17: Vidya Sunil Magare | D17: =VLOOKUP(C17,Workers!B:C,2) -> 135 | E17: 46043 | F17: MIDC | G17: Helpdesk | H17: Documents | I17: Priti | J17: 46043 | K17: Marathi | L17: 46043 | M17: Yes | N17: Solved | O17: Yes | P17: Scholarship
A18: 17 | B18: Hd_Q_15 | C18: Lata Bapu Patil | D18: =VLOOKUP(C18,Workers!B:C,2) -> 37 | E18: 46043 | F18: MIDC | G18: Helpdesk | H18: Documents | I18: Priti | J18: 46043 | K18: Marathi | L18: 46043 | M18: Yes | N18: Solved | O18: No | P18: Post office saving account
A19: 18 | B19: Hd_Q_17 | C19: Sarika Anil Kamble | D19: =VLOOKUP(C19,Workers!B:C,2) -> 89 | E19: 46043 | F19: MIDC | G19: Helpdesk | H19: Documents | I19: Priti | J19: 46043 | K19: Marathi | L19: 46043 | M19: Yes | N19: Solved | O19: No | P19: PPF
A20: 19 | B20: Hd_Q_18 | C20: Krutika Kishore Saware | D20: =VLOOKUP(C20,Workers!B:C,2) -> 35 | E20: 46043 | F20: MIDC | G20: Helpdesk | H20: Information | I20: Priti | J20: 46043 | K20: Marathi | L20: 46043 | M20: Yes | N20: Solved | O20: No | P20: Sukhanya Account
A21: 20 | B21: Hd_Q_19 | C21: Indravati Devi Sunil Kumar Jaiswal | D21: =VLOOKUP(C21,Workers!B:C,2) -> 24 | E21: 46043 | F21: MIDC | G21: Helpdesk | H21: Information | I21: Priti | J21: 46043 | K21: Hindi | L21: 46043 | M21: Yes | N21: Solved | O21: No | P21: Policy info
A22: 21 | B22: HR_Ad_Q_2 | C22: Shakti Suresh Pardeshi | D22: =VLOOKUP(C22,Workers!B:C,2) -> 533 | E22: 46044 | F22: Mumbai Central | G22: HR/Admin | H22: Grievance | I22: Grishma | J22: 46044 | K22: Hindi | L22: 46044 | M22: Yes | N22: Solved | O22: No | P22: Compliance
A23: 22 | B23: HR_Ad_Q_4 | C23: Hadiqa Jabir Shaikh | D23: =VLOOKUP(C23,Workers!B:C,2) -> 565 | E23: 46044 | F23: Mumbai Central | G23: HR/Admin | H23: Information | I23: Veena | J23: 46044 | K23: Hindi | L23: 46045 | M23: Yes | N23: Solved | O23: Yes | P23: PF Amount
A24: 23 | C24: Rehana Mubeen Sayed | D24: =VLOOKUP(C24,Workers!B:C,2) -> 522 | E24: 46044 | F24: Mumbai Central | G24: HR/Admin | H24: Information | I24: Veena | J24: 46044 | K24: Hindi | N24: Pending | P24: Holiday Detail
A25: 24 | B25: NG_Q_1 | C25: Dhanraj Suresh Pardeshi | D25: =VLOOKUP(C25,Workers!B:C,2) -> 512 | E25: 46044 | F25: Mumbai Central | G25: Others | H25: Grievance | J25: 46044 | K25: Hindi | N25: Pending | P25: Nextgen
A26: 25 | B26: Hd_Q_20 | C26: T Bama | D26: =VLOOKUP(C26,Workers!B:C,2) -> 110 | E26: 46044 | F26: MIDC | G26: Helpdesk | H26: Documents | I26: Priti | J26: 46044 | K26: Hindi | L26: 46044 | M26: Yes | N26: Solved | O26: No | P26: Name Change
A27: 26 | B27: Hd_Q_21 | C27: Kalaiyrashi Murgeshan Nadar | D27: =VLOOKUP(C27,Workers!B:C,2) -> 29 | E27: 46044 | F27: MIDC | G27: Helpdesk | H27: Documents | I27: Priti | J27: 46044 | K27: Hindi | L27: 46044 | M27: Yes | N27: Solved | O27: No | P27: Ayushman Card
A28: 27 | B28: HR_Ad_Q_5 | C28: Hemlata Avinash Pardeshi | D28: =VLOOKUP(C28,Workers!B:C,2) -> 513 | E28: 46044 | F28: Mumbai Central | G28: HR/Admin | H28: Information | I28: Veena | J28: 46044 | K28: Hindi | L28: 46045 | M28: Yes | N28: Solved | O28: Yes | P28: PF Amount
A29: 28 | B29: Hd_Q_23 | C29: Shila Rahul Sadaphule | D29: =VLOOKUP(C29,Workers!B:C,2) -> 95 | E29: 46044 | F29: MIDC | G29: Helpdesk | H29: Documents | I29: Priti | J29: 46044 | K29: Marathi | L29: 46044 | M29: Yes | N29: Solved | O29: Yes | P29: Aadhar delivery
A30: 29 | B30: Hd_Q_22 | C30: Nikita Ishwar Mahale | D30: =VLOOKUP(C30,Workers!B:C,2) -> 216 | E30: 46044 | F30: MIDC | G30: Helpdesk | H30: Documents | I30: Priti | J30: 46044 | K30: Marathi | L30: 46044 | M30: Yes | N30: Solved | O30: Yes | P30: Ration Card Name Update
A31: 30 | B31: Hd_Q_24 | C31: Rupali Pritesh Mirke | D31: =VLOOKUP(C31,Workers!B:C,2) -> 244 | E31: 46044 | F31: MIDC | G31: Helpdesk | H31: Documents | I31: Priti | J31: 46044 | K31: Marathi | L31: 46044 | M31: Yes | N31: Solved | O31: Yes | P31: Ayushman Card
A32: 31 | B32: P_Q_1 | C32: Babita Vilas Pardeshi | D32: =VLOOKUP(C32,Workers!B:C,2) -> 562 | E32: 46044 | F32: Mumbai Central | G32: Production | H32: Information | I32: Manjiri | J32: 46044 | K32: Hindi | L32: 46045 | M32: Yes | N32: Solved | O32: No | P32: Payment
A33: 32 | B33: HR_Ad_Q_6 | C33: Babita Vilas Pardeshi | D33: =VLOOKUP(C33,Workers!B:C,2) -> 562 | E33: 46044 | F33: Mumbai Central | G33: HR/Admin | H33: Information | I33: Veena | J33: 46044 | K33: Hindi | L33: 46045 | M33: Yes | N33: Solved | O33: Yes | P33: PF Amount
A34: 33 | B34: Hd_Q_25 | C34: Rekha Akash Pardeshi | D34: =VLOOKUP(C34,Workers!B:C,2) -> 523 | E34: 46044 | F34: Mumbai Central | G34: Helpdesk | H34: Information | I34: Dinesh | J34: 46044 | K34: Hindi | L34: 46044 | M34: Yes | N34: Solved | O34: Yes | P34: Ration Card Income Update
A35: 34 | B35: HR_Ad_Q_7 | C35: Sunaina Kalidas Pardeshi | D35: =VLOOKUP(C35,Workers!B:C,2) -> 561 | E35: 46044 | F35: Mumbai Central | G35: HR/Admin | H35: Information | I35: Veena | J35: 46045 | K35: Hindi | L35: 46045 | M35: Yes | N35: Solved | O35: Yes | P35: PF Amount
A36: 35 | C36: Madhuri Shesnarayan Tiwari | D36: =VLOOKUP(C36,Workers!B:C,2) -> 552 | E36: 46045 | F36: Mumbai Central | G36: HR/Admin | H36: Grievance | I36: Veena | J36: 46045 | K36: Hindi | N36: Pending | P36: Locker Issue
A37: 36 | B37: Hd_Q_29 | C37: Vandana Ranjeet Pardeshi | D37: =VLOOKUP(C37,Workers!B:C,2) -> 545 | E37: 46045 | F37: Mumbai Central | G37: Helpdesk | H37: Documents | I37: Dinesh | J37: 46045 | K37: Hindi | L37: 46046 | M37: Yes | N37: Solved | O37: Yes | P37: Ration Card Name Update
A38: 37 | C38: Bharti Vikram Pardeshi | D38: =VLOOKUP(C38,Workers!B:C,2) -> 511 | E38: 46045 | F38: Mumbai Central | G38: HR/Admin | H38: Information | I38: Bharati | J38: 46045 | K38: Hindi | N38: Pending | O38: Yes | P38: Holiday Detail
A39: 38 | B39: P_Q_2 | C39: Bharti Vikram Pardeshi | D39: =VLOOKUP(C39,Workers!B:C,2) -> 511 | E39: 46045 | F39: Mumbai Central | G39: Production | H39: Information | I39: Manjiri | J39: 46045 | K39: Hindi | L39: 46051 | M39: Yes | N39: Solved | O39: No | P39: Production Piece Details
A40: 39 | B40: HR_Ad_Q_3 | C40: Jyoti Danraj Pardeshi | D40: =VLOOKUP(C40,Workers!B:C,2) -> 587 | E40: 46045 | F40: Mumbai Central | G40: HR/Admin | H40: Information | I40: Veena | J40: 46045 | K40: Hindi | L40: 46045 | M40: Yes | N40: Solved | O40: Yes | P40: PF Amount
...

Sheet Workers
A1: Centre | B1: Worker Name | C1: Employee Code | D1: Gender | E1: Employment type | F1: Position | I1: Missing names | J1: Case | K1: Dep | L1: Received | M1: Sent VN | N1: Code
A2: BC | B2: Aaradhana Deepak Shinde | C2: 582 | D2: F | E2: Daily | F2: Bag Checking | I2: Renu Birju pardeshi | O2: Stitching
A3: MIDC | B3: Aarti Ashok Kirkire | C3: 139 | D3: F | E3: Fixed | F3: Stitching | I3: Shajaha ansari | J3: Loan case taken and resolved | K3: Priti | L3: 46053 | M3: 46057 | N3: Hd_Q_54 | O3: staff | P3: Hd_Q_54.1
A4: MIDC | B4: Aarti Krishna Shiral | C4: 1 | D4: F | E4: Fixed | F4: Stitching
A5: BC | B5: Aarti Raju Pardeshi | C5: 589 | D5: F | E5: Fixed | F5: supervisor
A6: BC | B6: Aashish Rameshbhai Rajput | C6: 543 | D6: F | E6: per pc | F6: Stitching
A7: MIDC | B7: Aditi Vilas Kadam | C7: 2 | D7: F | E7: Fixed | F7: Panel Checking
A8: MIDC | B8: Ahmed chacha | C8: L004 | D8: M | F8: Overlock
A9: MIDC | B9: Akshta Jitendra Berde | C9: 201 | E9: Fixed | F9: Stitching
A10: BC | B10: Alka Ravi Pardeshi | C10: 502 | D10: M | E10: per pc | F10: Stitching
A11: BC | B11: Anita Gopi Pardeshi | C11: 584 | D11: M | E11: Daily | F11: Packing
A12: MIDC | B12: Anita Uttam Khandagale | C12: 5 | D12: F | E12: Fixed | F12: Thread cutting
A13: BC | B13: Anjumbanu Salman Khan | C13: 508 | D13: F | E13: per pc | F13: Stitching
A14: MIDC | B14: Ankita Laxman Sutar | C14: 4 | D14: F | E14: Fixed | F14: Stitching
A15: MIDC | B15: Ankush Kashiram Hadal | C15: 232 | D15: M | E15: Daily | F15: Logistics
A16: BC | B16: Arati Gopal Pardeshi | C16: 603 | D16: F
B17: Archita Vikas Pardeshi
A18: MIDC | B18: Arpana Alpesh Pawar | C18: 6 | D18: F | E18: Fixed | F18: Bag checking
A19: BC | B19: Arti Kisan Pardeshi | C19: 598 | D19: M | E19: Fixed | F19: supervisor
A20: MIDC | B20: Arti Sharad Mohite | C20: 7 | D20: F | E20: Fixed | F20: Stitching
B21: Asha Ganesh Pardeshi
A22: BC | B22: Asha Kishor Betwala | C22: 583 | D22: F | E22: Daily | F22: Bag Checking
A23: MIDC | B23: Ashwini Ajay Mahale | C23: 9 | D23: F | E23: Fixed | F23: Stitching
B24: Ashwini Suresh Thapad
A25: BC | B25: Ayesha Abdul Shaikh | C25: 510 | D25: F | E25: per pc | F25: Stitching
A26: BC | B26: Ayyub Mehboob Khan | C26: 507 | D26: F | E26: per pc | F26: Stitching
A27: BC | B27: Babita Birju Pardeshi | C27: MCP79
A28: BC | B28: Babita Vilas Pardeshi | C28: 562 | D28: F | E28: per pc | F28: Stitching
A29: MIDC | B29: Beby Navsha Baraf | C29: 10 | D29: F | E29: Fixed | F29: House keeping
A30: MIDC | B30: Bhanumati Nadar | C30: 234 | D30: F | E30: Daily | F30: Stitching
A31: BC | B31: Bharati Harshanand Rasal | C31: 505 | D31: F | E31: per pc | F31: Stitching
A32: MIDC | B32: Bharti Ankush Page | C32: 11 | D32: F | E32: Fixed | F32: Stitching
A33: MIDC | B33: Bharti Arvind Tokare | C33: 250 | D33: F | E33: Daily | F33: Stitching
B34: Bharti Pared
A35: BC | B35: Bharti Vikram Pardeshi | C35: 511 | D35: F | E35: per pc | F35: Stitching
A36: BC | B36: Bhavana Nitin Pardeshi | C36: 546 | D36: F | E36: per pc | F36: Stitching
A37: MIDC | B37: Chanda Devi | C37: 12 | D37: F | E37: Fixed | F37: Thread cutting
A38: MIDC | B38: Chaya Babu Kurian | C38: 13 | D38: F | E38: Fixed | F38: Thread cutting
A39: MIDC | B39: Chhaya Arun Nikam | C39: 15 | D39: F | E39: Fixed | F39: Stitching
A40: MIDC | B40: Dakshta Tejas Kadam | C40: 16 | D40: F | E40: Fixed | F40: Panel Checking
...

Sheet Ai Platform
A1: Sr No. | B1: Name
A2: 1 | B2: Telnyx – Voice AI Agents
A3: 2 | B3: VocalRAG – Voice-First Knowledge AI Platform
A4: 3 | B4: Kriatix
A5: 4 | B5: Ameyo Voice Bot
A6: 5 | B6: byVoice
A7: 6 | B7: Amazon Lex
A8: 7 | B8: Convozen AI
A9: 8 | B9: Emergent
A10: 9 | B10: Open-Source (Intervo/VoxArena)
A11: 10 | B11: Salesforce Agentforce 360 / Voice
A12: 11 | B12: Google Dialogflow CX | C12: best fit for guard requirement
A13: 12 | B13: Amazon Connect + Lex | C13: best fit for guard requirement
A14: 13 | B14: Kore.ai | C14: best fit for guard requirement
A15: 14 | B15: Eleven lab - New version | C15: For whatsapp connection
A16: 15 | B16: GPT agent
A17: 16 | B17: VoiceGenie
